<?xml version="1.0"?>
<robot name="maze_bot" xmlns:xacro="http://www.ros.org/wiki/xacro">

  <!-- bot ist klein damit er in 1m breite cells passt.
       basis: 0.3 x 0.25 x 0.12 m, wheels radius 0.04 -->

  <xacro:property name="base_l" value="0.30" />
  <xacro:property name="base_w" value="0.25" />
  <xacro:property name="base_h" value="0.10" />
  <xacro:property name="wheel_r" value="0.04" />
  <xacro:property name="wheel_w" value="0.025" />
  <xacro:property name="wheel_sep" value="0.30" />

  <xacro:macro name="box_inertia" params="m x y z">
    <inertial>
      <mass value="${m}"/>
      <origin xyz="0 0 0" rpy="0 0 0"/>
      <inertia ixx="${m*(y*y+z*z)/12.0}" ixy="0" ixz="0"
               iyy="${m*(x*x+z*z)/12.0}" iyz="0"
               izz="${m*(x*x+y*y)/12.0}"/>
    </inertial>
  </xacro:macro>

  <xacro:macro name="cyl_inertia" params="m r l">
    <inertial>
      <mass value="${m}"/>
      <origin xyz="0 0 0" rpy="0 0 0"/>
      <inertia ixx="${m*(3*r*r+l*l)/12.0}" ixy="0" ixz="0"
               iyy="${m*(3*r*r+l*l)/12.0}" iyz="0"
               izz="${m*r*r/2.0}"/>
    </inertial>
  </xacro:macro>

  <link name="base_footprint"/>

  <link name="base_link">
    <visual>
      <geometry><box size="${base_l} ${base_w} ${base_h}"/></geometry>
      <material name="bot_blue"><color rgba="0.1 0.4 0.9 1"/></material>
    </visual>
    <collision>
      <geometry><box size="${base_l} ${base_w} ${base_h}"/></geometry>
    </collision>
    <xacro:box_inertia m="2.0" x="${base_l}" y="${base_w}" z="${base_h}"/>
  </link>

  <joint name="base_joint" type="fixed">
    <parent link="base_footprint"/>
    <child link="base_link"/>
    <origin xyz="0 0 ${wheel_r + base_h/2}"/>
  </joint>

  <!-- wheels -->
  <xacro:macro name="wheel" params="prefix y_offset">
    <link name="${prefix}_wheel">
      <visual>
        <geometry><cylinder radius="${wheel_r}" length="${wheel_w}"/></geometry>
        <origin rpy="${pi/2} 0 0"/>
        <material name="dark"><color rgba="0.1 0.1 0.1 1"/></material>
      </visual>
      <collision>
        <geometry><cylinder radius="${wheel_r}" length="${wheel_w}"/></geometry>
        <origin rpy="${pi/2} 0 0"/>
      </collision>
      <xacro:cyl_inertia m="0.2" r="${wheel_r}" l="${wheel_w}"/>
    </link>
    <joint name="${prefix}_wheel_joint" type="continuous">
      <parent link="base_link"/>
      <child link="${prefix}_wheel"/>
      <origin xyz="0 ${y_offset} ${-base_h/2}"/>
      <axis xyz="0 1 0"/>
    </joint>
  </xacro:macro>

  <xacro:wheel prefix="left"  y_offset="${ wheel_sep/2}"/>
  <xacro:wheel prefix="right" y_offset="${-wheel_sep/2}"/>

  <!-- caster für stabilität -->
  <link name="caster">
    <visual>
      <geometry><sphere radius="${wheel_r/2}"/></geometry>
      <material name="dark"/>
    </visual>
    <collision>
      <geometry><sphere radius="${wheel_r/2}"/></geometry>
    </collision>
    <inertial>
      <mass value="0.1"/>
      <origin xyz="0 0 0"/>
      <inertia ixx="0.0001" ixy="0" ixz="0" iyy="0.0001" iyz="0" izz="0.0001"/>
    </inertial>
  </link>
  <joint name="caster_joint" type="fixed">
    <parent link="base_link"/>
    <child link="caster"/>
    <origin xyz="${base_l/2 - 0.04} 0 ${-base_h/2 - wheel_r/2}"/>
  </joint>

  <!-- lidar oben drauf -->
  <link name="lidar_link">
    <visual>
      <geometry><cylinder radius="0.04" length="0.04"/></geometry>
      <material name="lidar_red"><color rgba="0.8 0.1 0.1 1"/></material>
    </visual>
    <collision>
      <geometry><cylinder radius="0.04" length="0.04"/></geometry>
    </collision>
    <xacro:cyl_inertia m="0.1" r="0.04" l="0.04"/>
  </link>
  <joint name="lidar_joint" type="fixed">
    <parent link="base_link"/>
    <child link="lidar_link"/>
    <origin xyz="0 0 ${base_h/2 + 0.02}"/>
  </joint>

  <!-- gazebo plugins -->
  <gazebo>
    <plugin filename="gz-sim-diff-drive-system" name="gz::sim::systems::DiffDrive">
      <left_joint>left_wheel_joint</left_joint>
      <right_joint>right_wheel_joint</right_joint>
      <wheel_separation>${wheel_sep}</wheel_separation>
      <wheel_radius>${wheel_r}</wheel_radius>
      <topic>cmd_vel</topic>
      <odom_topic>odom</odom_topic>
      <frame_id>odom</frame_id>
      <child_frame_id>base_footprint</child_frame_id>
      <odom_publish_frequency>30</odom_publish_frequency>
      <tf_topic>tf</tf_topic>
    </plugin>

    <plugin filename="gz-sim-joint-state-publisher-system"
            name="gz::sim::systems::JointStatePublisher">
      <topic>joint_states</topic>
    </plugin>

    <plugin filename="gz-sim-pose-publisher-system"
            name="gz::sim::systems::PosePublisher">
      <publish_link_pose>true</publish_link_pose>
      <use_pose_vector_msg>true</use_pose_vector_msg>
      <static_publisher>true</static_publisher>
      <static_update_frequency>1</static_update_frequency>
    </plugin>
  </gazebo>

  <gazebo reference="lidar_link">
    <sensor name="lidar" type="gpu_lidar">
      <update_rate>10</update_rate>
      <topic>scan</topic>
      <gz_frame_id>lidar_link</gz_frame_id>
      <ray>
        <scan>
          <horizontal>
            <samples>360</samples>
            <resolution>1</resolution>
            <min_angle>-3.14159</min_angle>
            <max_angle>3.14159</max_angle>
          </horizontal>
          <vertical>
            <samples>1</samples>
            <min_angle>0</min_angle>
            <max_angle>0</max_angle>
          </vertical>
        </scan>
        <range>
          <min>0.08</min>
          <max>8.0</max>
          <resolution>0.01</resolution>
        </range>
      </ray>
      <always_on>1</always_on>
      <visualize>true</visualize>
    </sensor>
  </gazebo>

</robot>
